Workbook

Sheet Datos
P1: DISTRIBUCIÓN
B2: PROPÓSITO, METAS Y VALORES | C2: A | D2: B | E2: C | F2: D | G2: E | H2: F | I2: G | J2: H | K2: I | L2: J | M2: K | N2: L | O2: PROMEDIO | P2: 1 Para nada | Q2: 2 Escasamente | R2: 3 Medianamente | S2: 4 En gran medida | T2: 5 Totalmente | U2: TOTAL
B3: 1. El equipo tiene un propósito común que es inspirador y entusiasma a sus miembros. El propósito “captura el corazón y el alma” de los miembros del equipo. | C3: 3 | D3: 2 | E3: 4 | F3: 3 | G3: 4 | H3: 3 | I3: 3 | J3: 3 | K3: 3 | L3: 4 | M3: 4 | O3: =AVERAGE(C3:M3) -> 3.2727273 | P3: =COUNTIF($C3:$N3,1) -> 0 | Q3: =COUNTIF($C3:$N3,2) -> 1 | R3: =COUNTIF($C3:$N3,3) -> 6 | S3: =COUNTIF($C3:$N3,4) -> 4 | T3: =COUNTIF($C3:$N3,5) -> 0 | U3: =SUM(P3:T3) -> 11
B4: 2. El equipo tiene la capacidad de comunicar dicho propósito al resto de su estructura. | C4: 2 | D4: 2 | E4: 3 | F4: 3 | G4: 4 | H4: 2 | I4: 4 | J4: 4 | K4: 3 | L4: 3 | M4: 3 | O4: =AVERAGE(C4:M4) -> 3 | P4: =COUNTIF($C4:$N4,1) -> 0 | Q4: =COUNTIF($C4:$N4,2) -> 3 | R4: =COUNTIF($C4:$N4,3) -> 5 | S4: =COUNTIF($C4:$N4,4) -> 3 | T4: =COUNTIF($C4:$N4,5) -> 0 | U4: =SUM(P4:T4) -> 11
B5: 3. El equipo tiene claro cómo su propósito se conecta y contribuye con el propósito último de la organización. | C5: 3 | D5: 3 | E5: 4 | F5: 5 | G5: 4 | H5: 3 | I5: 4 | J5: 4 | K5: 3 | L5: 4 | M5: 5 | O5: =AVERAGE(C5:M5) -> 3.8181818 | P5: =COUNTIF($C5:$N5,1) -> 0 | Q5: =COUNTIF($C5:$N5,2) -> 0 | R5: =COUNTIF($C5:$N5,3) -> 4 | S5: =COUNTIF($C5:$N5,4) -> 5 | T5: =COUNTIF($C5:$N5,5) -> 2 | U5: =SUM(P5:T5) -> 11
B6: 4. El equipo tiene claros sus objetivos o metas de desempeño. | C6: 3 | D6: 4 | E6: 4 | F6: 4 | G6: 3 | H6: 3 | I6: 3 | J6: 4 | K6: 4 | L6: 3 | M6: 5 | O6: =AVERAGE(C6:M6) -> 3.6363636 | P6: =COUNTIF($C6:$N6,1) -> 0 | Q6: =COUNTIF($C6:$N6,2) -> 0 | R6: =COUNTIF($C6:$N6,3) -> 5 | S6: =COUNTIF($C6:$N6,4) -> 5 | T6: =COUNTIF($C6:$N6,5) -> 1 | U6: =SUM(P6:T6) -> 11
B7: 5. El proceso de planificación estratégica de la organización se basa en las metas de desempeño de este equipo. | C7: 3 | D7: 4 | E7: 4 | F7: 4 | G7: 3 | H7: 4 | I7: 2 | J7: 3 | K7: 2 | L7: 2 | M7: 4 | O7: =AVERAGE(C7:M7) -> 3.1818182 | P7: =COUNTIF($C7:$N7,1) -> 0 | Q7: =COUNTIF($C7:$N7,2) -> 3 | R7: =COUNTIF($C7:$N7,3) -> 3 | S7: =COUNTIF($C7:$N7,4) -> 5 | T7: =COUNTIF($C7:$N7,5) -> 0 | U7: =SUM(P7:T7) -> 11
B8: 6. Existen métricas para los objetivos de desempeño del equipo. | C8: 1 | D8: 4 | E8: 2 | F8: 3 | G8: 2 | H8: 2 | I8: 1 | J8: 3 | K8: 2 | L8: 3 | M8: 4 | O8: =AVERAGE(C8:M8) -> 2.4545455 | P8: =COUNTIF($C8:$N8,1) -> 2 | Q8: =COUNTIF($C8:$N8,2) -> 4 | R8: =COUNTIF($C8:$N8,3) -> 3 | S8: =COUNTIF($C8:$N8,4) -> 2 | T8: =COUNTIF($C8:$N8,5) -> 0 | U8: =SUM(P8:T8) -> 11
B9: 7. Los objetivos del equipo quedan registrados en un documento “vivo” al que se recurre y revisa periódicamente. | C9: 3 | D9: 2 | E9: 3 | F9: 2 | G9: 2 | H9: 2 | I9: 2 | J9: 3 | K9: 2 | L9: 2 | M9: 2 | O9: =AVERAGE(C9:M9) -> 2.2727273 | P9: =COUNTIF($C9:$N9,1) -> 0 | Q9: =COUNTIF($C9:$N9,2) -> 8 | R9: =COUNTIF($C9:$N9,3) -> 3 | S9: =COUNTIF($C9:$N9,4) -> 0 | T9: =COUNTIF($C9:$N9,5) -> 0 | U9: =SUM(P9:T9) -> 11
B10: 8. El equipo reflexiona acerca de los riesgos para alcanzar las metas individuales, y discute planes para su contingencia. | C10: 2 | D10: 2 | E10: 3 | F10: 3 | G10: 3 | H10: 3 | I10: 2 | J10: 4 | K10: 2 | L10: 3 | M10: 2 | O10: =AVERAGE(C10:M10) -> 2.6363636 | P10: =COUNTIF($C10:$N10,1) -> 0 | Q10: =COUNTIF($C10:$N10,2) -> 5 | R10: =COUNTIF($C10:$N10,3) -> 5 | S10: =COUNTIF($C10:$N10,4) -> 1 | T10: =COUNTIF($C10:$N10,5) -> 0 | U10: =SUM(P10:T10) -> 11
B11: 9. Cada miembro del equipo demuestra alineamiento con los valores de la empresa y un elevado nivel de integridad personal. | C11: 4 | D11: 3 | E11: 4 | F11: 5 | G11: 3 | H11: 5 | I11: 3 | J11: 4 | K11: 3 | L11: 4 | M11: 4 | O11: =AVERAGE(C11:M11) -> 3.8181818 | P11: =COUNTIF($C11:$N11,1) -> 0 | Q11: =COUNTIF($C11:$N11,2) -> 0 | R11: =COUNTIF($C11:$N11,3) -> 4 | S11: =COUNTIF($C11:$N11,4) -> 5 | T11: =COUNTIF($C11:$N11,5) -> 2 | U11: =SUM(P11:T11) -> 11
B12: ROLES Y RESPONSABILIDADES | P12: =COUNTIF($C12:$N12,1) -> 0 | Q12: =COUNTIF($C12:$N12,2) -> 0 | R12: =COUNTIF($C12:$N12,3) -> 0 | S12: =COUNTIF($C12:$N12,4) -> 0 | T12: =COUNTIF($C12:$N12,5) -> 0 | U12: =SUM(P12:T12) -> 0
B13: 1. Los roles dentro del equipo están claramente definidos y acordados. | C13: 4 | D13: 5 | E13: 4 | F13: 4 | G13: 4 | H13: 4 | I13: 4 | J13: 4 | K13: 3 | L13: 4 | M13: 5 | O13: =AVERAGE(C13:M13) -> 4.0909091 | P13: =COUNTIF($C13:$N13,1) -> 0 | Q13: =COUNTIF($C13:$N13,2) -> 0 | R13: =COUNTIF($C13:$N13,3) -> 1 | S13: =COUNTIF($C13:$N13,4) -> 8 | T13: =COUNTIF($C13:$N13,5) -> 2 | U13: =SUM(P13:T13) -> 11
B14: 2. Las interdependencias entre miembros están claramente definidas y funcionan cabalmente. | C14: 3 | D14: 4 | E14: 4 | F14: 5 | G14: 4 | H14: 4 | I14: 4 | J14: 4 | K14: 3 | L14: 2 | M14: 4 | O14: =AVERAGE(C14:M14) -> 3.7272727 | P14: =COUNTIF($C14:$N14,1) -> 0 | Q14: =COUNTIF($C14:$N14,2) -> 1 | R14: =COUNTIF($C14:$N14,3) -> 2 | S14: =COUNTIF($C14:$N14,4) -> 7 | T14: =COUNTIF($C14:$N14,5) -> 1 | U14: =SUM(P14:T14) -> 11
B15: 3. Las metas individuales y su conexión con las metas y objetivos del equipo están definidas claramente. | C15: 3 | D15: 3 | E15: 3 | F15: 5 | G15: 3 | H15: 4 | I15: 4 | J15: 4 | K15: 3 | L15: 3 | M15: 4 | O15: =AVERAGE(C15:M15) -> 3.5454545 | P15: =COUNTIF($C15:$N15,1) -> 0 | Q15: =COUNTIF($C15:$N15,2) -> 0 | R15: =COUNTIF($C15:$N15,3) -> 6 | S15: =COUNTIF($C15:$N15,4) -> 4 | T15: =COUNTIF($C15:$N15,5) -> 1 | U15: =SUM(P15:T15) -> 11
B16: 4. Los integrantes del equipo se consideran mutua e individualmente responsables ante metas colectivas. | C16: 3 | D16: 2 | E16: 4 | F16: 4 | G16: 4 | H16: 4 | I16: 2 | J16: 3 | K16: 2 | L16: 3 | M16: 4 | O16: =AVERAGE(C16:M16) -> 3.1818182 | P16: =COUNTIF($C16:$N16,1) -> 0 | Q16: =COUNTIF($C16:$N16,2) -> 3 | R16: =COUNTIF($C16:$N16,3) -> 3 | S16: =COUNTIF($C16:$N16,4) -> 5 | T16: =COUNTIF($C16:$N16,5) -> 0 | U16: =SUM(P16:T16) -> 11
B17: 5. El rol del líder está claramente definido y los miembros tienen un entendimiento común de éste. | C17: 3 | D17: 3 | E17: 4 | F17: 5 | G17: 4 | H17: 3 | I17: 3 | J17: 3 | K17: 3 | L17: 4 | M17: 4 | O17: =AVERAGE(C17:M17) -> 3.5454545 | P17: =COUNTIF($C17:$N17,1) -> 0 | Q17: =COUNTIF($C17:$N17,2) -> 0 | R17: =COUNTIF($C17:$N17,3) -> 6 | S17: =COUNTIF($C17:$N17,4) -> 4 | T17: =COUNTIF($C17:$N17,5) -> 1 | U17: =SUM(P17:T17) -> 11
B18: 6. Los miembros del equipo cumplen con sus promesas demostrando compromiso respecto de las metas y objetivos individuales. | C18: 4 | D18: 3 | E18: 4 | F18: 4 | G18: 4 | H18: 4 | I18: 4 | J18: 4 | K18: 3 | L18: 4 | M18: 4 | O18: =AVERAGE(C18:M18) -> 3.8181818 | P18: =COUNTIF($C18:$N18,1) -> 0 | Q18: =COUNTIF($C18:$N18,2) -> 0 | R18: =COUNTIF($C18:$N18,3) -> 2 | S18: =COUNTIF($C18:$N18,4) -> 9 | T18: =COUNTIF($C18:$N18,5) -> 0 | U18: =SUM(P18:T18) -> 11
B19: 7. Los miembros del equipo están dispuestos a realizar sacrificios y compartir recursos para optimizar la efectividad del equipo en el logro de las metas. | C19: 2 | D19: 3 | E19: 3 | F19: 5 | G19: 4 | H19: 4 | I19: 3 | J19: 4 | K19: 3 | L19: 4 | M19: 3 | O19: =AVERAGE(C19:M19) -> 3.4545455 | P19: =COUNTIF($C19:$N19,1) -> 0 | Q19: =COUNTIF($C19:$N19,2) -> 1 | R19: =COUNTIF($C19:$N19,3) -> 5 | S19: =COUNTIF($C19:$N19,4) -> 4 | T19: =COUNTIF($C19:$N19,5) -> 1 | U19: =SUM(P19:T19) -> 11
B20: 8. El equipo dedica tiempo a crecer como tal, aumentando el sentido de la solidaridad entre sus miembros. | C20: 3 | D20: 4 | E20: 4 | F20: 5 | G20: 5 | H20: 4 | I20: 4 | J20: 4 | K20: 2 | L20: 4 | M20: 3 | O20: =AVERAGE(C20:M20) -> 3.8181818 | P20: =COUNTIF($C20:$N20,1) -> 0 | Q20: =COUNTIF($C20:$N20,2) -> 1 | R20: =COUNTIF($C20:$N20,3) -> 2 | S20: =COUNTIF($C20:$N20,4) -> 6 | T20: =COUNTIF($C20:$N20,5) -> 2 | U20: =SUM(P20:T20) -> 11
B21: PROCESOS | P21: =COUNTIF($C21:$N21,1) -> 0 | Q21: =COUNTIF($C21:$N21,2) -> 0 | R21: =COUNTIF($C21:$N21,3) -> 0 | S21: =COUNTIF($C21:$N21,4) -> 0 | T21: =COUNTIF($C21:$N21,5) -> 0 | U21: =SUM(P21:T21) -> 0
B22: 1. Existen acuerdos operativos o reglas de funcionamiento definidas para el equipo. | C22: 4 | D22: 2 | E22: 4 | F22: 5 | G22: 4 | H22: 4 | I22: 3 | J22: 4 | K22: 2 | L22: 4 | M22: 3 | O22: =AVERAGE(C22:M22) -> 3.5454545 | P22: =COUNTIF($C22:$N22,1) -> 0 | Q22: =COUNTIF($C22:$N22,2) -> 2 | R22: =COUNTIF($C22:$N22,3) -> 2 | S22: =COUNTIF($C22:$N22,4) -> 6 | T22: =COUNTIF($C22:$N22,5) -> 1 | U22: =SUM(P22:T22) -> 11
B23: 2. Se revisan periódicamente los procesos en base a su efectividad. | C23: 4 | D23: 1 | E23: 3 | F23: 4 | G23: 3 | H23: 3 | I23: 1 | J23: 3 | K23: 2 | L23: 3 | M23: 4 | O23: =AVERAGE(C23:M23) -> 2.8181818 | P23: =COUNTIF($C23:$N23,1) -> 2 | Q23: =COUNTIF($C23:$N23,2) -> 1 | R23: =COUNTIF($C23:$N23,3) -> 5 | S23: =COUNTIF($C23:$N23,4) -> 3 | T23: =COUNTIF($C23:$N23,5) -> 0 | U23: =SUM(P23:T23) -> 11
B24: 3. La utilización de los recursos del equipo [tiempo y habilidades de sus integrantes] es efectiva. | C24: 5 | D24: 3 | E24: 4 | F24: 5 | G24: 4 | H24: 5 | I24: 3 | J24: 4 | K24: 3 | L24: 4 | M24: 4 | O24: =AVERAGE(C24:M24) -> 4 | P24: =COUNTIF($C24:$N24,1) -> 0 | Q24: =COUNTIF($C24:$N24,2) -> 0 | R24: =COUNTIF($C24:$N24,3) -> 3 | S24: =COUNTIF($C24:$N24,4) -> 5 | T24: =COUNTIF($C24:$N24,5) -> 3 | U24: =SUM(P24:T24) -> 11
B25: 4. Está claro el producto de cada interacción o reunión, tanto del equipo como de los sub-equipos. | C25: 3 | D25: 1 | E25: 3 | F25: 3 | G25: 3 | H25: 4 | I25: 3 | J25: 4 | K25: 3 | L25: 3 | M25: 4 | O25: =AVERAGE(C25:M25) -> 3.0909091 | P25: =COUNTIF($C25:$N25,1) -> 1 | Q25: =COUNTIF($C25:$N25,2) -> 0 | R25: =COUNTIF($C25:$N25,3) -> 7 | S25: =COUNTIF($C25:$N25,4) -> 3 | T25: =COUNTIF($C25:$N25,5) -> 0 | U25: =SUM(P25:T25) -> 11
B26: 5. Se utilizan mecanismos de registro que facilitan el seguimiento de los compromisos. | C26: 4 | D26: 2 | E26: 4 | F26: 4 | G26: 3 | H26: 3 | I26: 3 | J26: 4 | K26: 3 | L26: 3 | M26: 3 | O26: =AVERAGE(C26:M26) -> 3.2727273 | P26: =COUNTIF($C26:$N26,1) -> 0 | Q26: =COUNTIF($C26:$N26,2) -> 1 | R26: =COUNTIF($C26:$N26,3) -> 6 | S26: =COUNTIF($C26:$N26,4) -> 4 | T26: =COUNTIF($C26:$N26,5) -> 0 | U26: =SUM(P26:T26) -> 11
B27: 6. La información circula con la fluidez necesaria para posibilitar la contribución efectiva de los miembros. | C27: 3 | D27: 4 | E27: 3 | F27: 5 | G27: 4 | H27: 4 | I27: 3 | J27: 4 | K27: 3 | L27: 4 | M27: 5 | O27: =AVERAGE(C27:M27) -> 3.8181818 | P27: =COUNTIF($C27:$N27,1) -> 0 | Q27: =COUNTIF($C27:$N27,2) -> 0 | R27: =COUNTIF($C27:$N27,3) -> 4 | S27: =COUNTIF($C27:$N27,4) -> 5 | T27: =COUNTIF($C27:$N27,5) -> 2 | U27: =SUM(P27:T27) -> 11
B28: 7. Existen procesos adecuados para la resolución de conflictos y toma de decisiones. | C28: 4 | D28: 1 | E28: 2 | F28: 4 | G28: 3 | H28: 4 | I28: 3 | J28: 4 | K28: 2 | L28: 3 | M28: 3 | O28: =AVERAGE(C28:M28) -> 3 | P28: =COUNTIF($C28:$N28,1) -> 1 | Q28: =COUNTIF($C28:$N28,2) -> 2 | R28: =COUNTIF($C28:$N28,3) -> 4 | S28: =COUNTIF($C28:$N28,4) -> 4 | T28: =COUNTIF($C28:$N28,5) -> 0 | U28: =SUM(P28:T28) -> 11
B29: 8. Los conflictos se resuelven en forma constructiva. | C29: 4 | D29: 4 | E29: 3 | F29: 4 | G29: 4 | H29: 4 | I29: 3 | J29: 4 | K29: 3 | L29: 4 | M29: 4 | O29: =AVERAGE(C29:M29) -> 3.7272727 | P29: =COUNTIF($C29:$N29,1) -> 0 | Q29: =COUNTIF($C29:$N29,2) -> 0 | R29: =COUNTIF($C29:$N29,3) -> 3 | S29: =COUNTIF($C29:$N29,4) -> 8 | T29: =COUNTIF($C29:$N29,5) -> 0 | U29: =SUM(P29:T29) -> 11
B30: 9. Los procesos son simples, mínimos y flexibles. | C30: 4 | D30: 1 | E30: 2 | F30: 5 | G30: 3 | H30: 4 | I30: 2 | J30: 3 | K30: 2 | L30: 2 | M30: 3 | O30: =AVERAGE(C30:M30) -> 2.8181818 | P30: =COUNTIF($C30:$N30,1) -> 1 | Q30: =COUNTIF($C30:$N30,2) -> 4 | R30: =COUNTIF($C30:$N30,3) -> 3 | S30: =COUNTIF($C30:$N30,4) -> 2 | T30: =COUNTIF($C30:$N30,5) -> 1 | U30: =SUM(P30:T30) -> 11
B31: RELACIONES | P31: =COUNTIF($C31:$N31,1) -> 0 | Q31: =COUNTIF($C31:$N31,2) -> 0 | R31: =COUNTIF($C31:$N31,3) -> 0 | S31: =COUNTIF($C31:$N31,4) -> 0 | T31: =COUNTIF($C31:$N31,5) -> 0 | U31: =SUM(P31:T31) -> 0
B32: 1. Existe apertura en el equipo para escucharse, desafiarse y vivir con la tensión necesaria para generar cambios. | C32: 4 | D32: 3 | E32: 4 | F32: 4 | G32: 4 | H32: 4 | I32: 3 | J32: 4 | K32: 3 | L32: 4 | M32: 3 | O32: =AVERAGE(C32:M32) -> 3.6363636 | P32: =COUNTIF($C32:$N32,1) -> 0 | Q32: =COUNTIF($C32:$N32,2) -> 0 | R32: =COUNTIF($C32:$N32,3) -> 4 | S32: =COUNTIF($C32:$N32,4) -> 7 | T32: =COUNTIF($C32:$N32,5) -> 0 | U32: =SUM(P32:T32) -> 11
B33: 2. No hay temas indiscutibles en el equipo: todos los temas se traen a la mesa y discuten abiertamente. | C33: 4 | D33: 4 | E33: 3 | F33: 5 | G33: 4 | H33: 4 | I33: 2 | J33: 3 | K33: 3 | L33: 3 | M33: 3 | O33: =AVERAGE(C33:M33) -> 3.4545455 | P33: =COUNTIF($C33:$N33,1) -> 0 | Q33: =COUNTIF($C33:$N33,2) -> 1 | R33: =COUNTIF($C33:$N33,3) -> 5 | S33: =COUNTIF($C33:$N33,4) -> 4 | T33: =COUNTIF($C33:$N33,5) -> 1 | U33: =SUM(P33:T33) -> 11
B34: 3. Los miembros del equipo se dan y reciben retroalimentación sobre comportamientos en tiempo real. | C34: 3 | D34: 1 | E34: 3 | F34: 4 | G34: 3 | H34: 4 | I34: 2 | J34: 3 | K34: 2 | L34: 3 | M34: 3 | O34: =AVERAGE(C34:M34) -> 2.8181818 | P34: =COUNTIF($C34:$N34,1) -> 1 | Q34: =COUNTIF($C34:$N34,2) -> 2 | R34: =COUNTIF($C34:$N34,3) -> 6 | S34: =COUNTIF($C34:$N34,4) -> 2 | T34: =COUNTIF($C34:$N34,5) -> 0 | U34: =SUM(P34:T34) -> 11
B35: 4. Existe respeto incondicional entre los integrantes, y se utilizan las diferencias de opiniones y fortalezas a favor del equipo. | C35: 4 | D35: 4 | E35: 4 | F35: 4 | G35: 4 | H35: 4 | I35: 4 | J35: 3 | K35: 3 | L35: 4 | M35: 2 | O35: =AVERAGE(C35:M35) -> 3.6363636 | P35: =COUNTIF($C35:$N35,1) -> 0 | Q35: =COUNTIF($C35:$N35,2) -> 1 | R35: =COUNTIF($C35:$N35,3) -> 2 | S35: =COUNTIF($C35:$N35,4) -> 8 | T35: =COUNTIF($C35:$N35,5) -> 0 | U35: =SUM(P35:T35) -> 11
B36: 5. El equipo contribuye y alienta a cada integrante a sacar y dar lo mejor de sí. | C36: 3 | D36: 2 | E36: 4 | F36: 4 | G36: 4 | H36: 4 | I36: 3 | J36: 4 | K36: 2 | L36: 3 | M36: 3 | O36: =AVERAGE(C36:M36) -> 3.2727273 | P36: =COUNTIF($C36:$N36,1) -> 0 | Q36: =COUNTIF($C36:$N36,2) -> 2 | R36: =COUNTIF($C36:$N36,3) -> 4 | S36: =COUNTIF($C36:$N36,4) -> 5 | T36: =COUNTIF($C36:$N36,5) -> 0 | U36: =SUM(P36:T36) -> 11
B37: 6. Los miembros del equipo confían en la habilidad del otro, la colaboración, y el apoyo mutuo. | C37: 4 | D37: 3 | E37: 4 | F37: 4 | G37: 4 | H37: 3 | I37: 2 | J37: 3 | K37: 3 | L37: 4 | M37: 3 | O37: =AVERAGE(C37:M37) -> 3.3636364 | P37: =COUNTIF($C37:$N37,1) -> 0 | Q37: =COUNTIF($C37:$N37,2) -> 1 | R37: =COUNTIF($C37:$N37,3) -> 5 | S37: =COUNTIF($C37:$N37,4) -> 5 | T37: =COUNTIF($C37:$N37,5) -> 0 | U37: =SUM(P37:T37) -> 11
B38: 7. Las emociones, los modelos mentales, y los valores individuales se utilizan para el logro de los resultados del equipo. | C38: 3 | D38: 2 | E38: 3 | F38: 3 | G38: 4 | H38: 3 | I38: 2 | J38: 4 | K38: 2 | L38: 3 | M38: 4 | O38: =AVERAGE(C38:M38) -> 3 | P38: =COUNTIF($C38:$N38,1) -> 0 | Q38: =COUNTIF($C38:$N38,2) -> 3 | R38: =COUNTIF($C38:$N38,3) -> 5 | S38: =COUNTIF($C38:$N38,4) -> 3 | T38: =COUNTIF($C38:$N38,5) -> 0 | U38: =SUM(P38:T38) -> 11
B39: 8. Son vistos por los demás como un grupo unido que resulta atractivo a personas que no pertenecen a él. | C39: 3 | D39: 1 | E39: 3 | F39: 4 | G39: 3 | H39: 3 | I39: 3 | J39: 3 | K39: 2 | L39: 2 | M39: 2 | O39: =AVERAGE(C39:M39) -> 2.6363636 | P39: =COUNTIF($C39:$N39,1) -> 1 | Q39: =COUNTIF($C39:$N39,2) -> 3 | R39: =COUNTIF($C39:$N39,3) -> 6 | S39: =COUNTIF($C39:$N39,4) -> 1 | T39: =COUNTIF($C39:$N39,5) -> 0 | U39: =SUM(P39:T39) -> 11
U40: =SUM(P40:T40) -> 0

Sheet Resultados por pregunta
B1: 1 | C1: 2 | D1: 3 | E1: 4 | F1: 5
A2: =Datos!B2 -> PROPÓSITO, METAS Y VALORES | B2: 1 Para nada | C2: 2 Escasamente | D2: 3 Medianamente | E2: 4 En gran medida | F2: 5 Totalmente | G2: Promedio Ponderado
A3: =Datos!B3 -> 1. El equipo tiene un propósito común que es inspirador y entusiasma a sus miembros. El propósito “captura el corazón y el alma” de los miembros del equipo. | B3: =Datos!P3 -> 0 | C3: =Datos!Q3 -> 1 | D3: =Datos!R3 -> 6 | E3: =Datos!S3 -> 4 | F3: =Datos!T3 -> 0 | G3: =SUMPRODUCT(B3:F3,$B$1:$F$1)/SUM(B3:F3) -> 3.2727273
A12: =Datos!B4 -> 2. El equipo tiene la capacidad de comunicar dicho propósito al resto de su estructura. | B12: =Datos!P4 -> 0 | C12: =Datos!Q4 -> 3 | D12: =Datos!R4 -> 5 | E12: =Datos!S4 -> 3 | F12: =Datos!T4 -> 0 | G12: =SUMPRODUCT(B12:F12,$B$1:$F$1)/SUM(B12:F12) -> 3
A24: =Datos!B5 -> 3. El equipo tiene claro cómo su propósito se conecta y contribuye con el propósito último de la organización. | B24: =Datos!P5 -> 0 | C24: =Datos!Q5 -> 0 | D24: =Datos!R5 -> 4 | E24: =Datos!S5 -> 5 | F24: =Datos!T5 -> 2 | G24: =SUMPRODUCT(B24:F24,$B$1:$F$1)/SUM(B24:F24) -> 3.8181818
A36: =Datos!B6 -> 4. El equipo tiene claros sus objetivos o metas de desempeño. | B36: =Datos!P6 -> 0 | C36: =Datos!Q6 -> 0 | D36: =Datos!R6 -> 5 | E36: =Datos!S6 -> 5 | F36: =Datos!T6 -> 1 | G36: =SUMPRODUCT(B36:F36,$B$1:$F$1)/SUM(B36:F36) -> 3.6363636
A48: =Datos!B7 -> 5. El proceso de planificación estratégica de la organización se basa en las metas de desempeño de este equipo. | B48: =Datos!P7 -> 0 | C48: =Datos!Q7 -> 3 | D48: =Datos!R7 -> 3 | E48: =Datos!S7 -> 5 | F48: =Datos!T7 -> 0 | G48: =SUMPRODUCT(B48:F48,$B$1:$F$1)/SUM(B48:F48) -> 3.1818182
A60: =Datos!B8 -> 6. Existen métricas para los objetivos de desempeño del equipo. | B60: =Datos!P8 -> 2 | C60: =Datos!Q8 -> 4 | D60: =Datos!R8 -> 3 | E60: =Datos!S8 -> 2 | F60: =Datos!T8 -> 0 | G60: =SUMPRODUCT(B60:F60,$B$1:$F$1)/SUM(B60:F60) -> 2.4545455
A72: =Datos!B9 -> 7. Los objetivos del equipo quedan registrados en un documento “vivo” al que se recurre y revisa periódicamente. | B72: =Datos!P9 -> 0 | C72: =Datos!Q9 -> 8 | D72: =Datos!R9 -> 3 | E72: =Datos!S9 -> 0 | F72: =Datos!T9 -> 0 | G72: =SUMPRODUCT(B72:F72,$B$1:$F$1)/SUM(B72:F72) -> 2.2727273
A84: =Datos!B10 -> 8. El equipo reflexiona acerca de los riesgos para alcanzar las metas individuales, y discute planes para su contingencia. | B84: =Datos!P10 -> 0 | C84: =Datos!Q10 -> 5 | D84: =Datos!R10 -> 5 | E84: =Datos!S10 -> 1 | F84: =Datos!T10 -> 0 | G84: =SUMPRODUCT(B84:F84,$B$1:$F$1)/SUM(B84:F84) -> 2.6363636
A96: =Datos!B11 -> 9. Cada miembro del equipo demuestra alineamiento con los valores de la empresa y un elevado nivel de integridad personal. | B96: =Datos!P11 -> 0 | C96: =Datos!Q11 -> 0 | D96: =Datos!R11 -> 4 | E96: =Datos!S11 -> 5 | F96: =Datos!T11 -> 2 | G96: =SUMPRODUCT(B96:F96,$B$1:$F$1)/SUM(B96:F96) -> 3.8181818
A109: =Datos!B12 -> ROLES Y RESPONSABILIDADES
A110: =Datos!B13 -> 1. Los roles dentro del equipo están claramente definidos y acordados. | B110: =Datos!P13 -> 0 | C110: =Datos!Q13 -> 0 | D110: =Datos!R13 -> 1 | E110: =Datos!S13 -> 8 | F110: =Datos!T13 -> 2 | G110: =SUMPRODUCT(B110:F110,$B$1:$F$1)/SUM(B110:F110) -> 4.0909091
A122: =Datos!B14 -> 2. Las interdependencias entre miembros están claramente definidas y funcionan cabalmente. | B122: =Datos!P14 -> 0 | C122: =Datos!Q14 -> 1 | D122: =Datos!R14 -> 2 | E122: =Datos!S14 -> 7 | F122: =Datos!T14 -> 1 | G122: =SUMPRODUCT(B122:F122,$B$1:$F$1)/SUM(B122:F122) -> 3.7272727
A134: =Datos!B15 -> 3. Las metas individuales y su conexión con las metas y objetivos del equipo están definidas claramente. | B134: =Datos!P15 -> 0 | C134: =Datos!Q15 -> 0 | D134: =Datos!R15 -> 6 | E134: =Datos!S15 -> 4 | F134: =Datos!T15 -> 1 | G134: =SUMPRODUCT(B134:F134,$B$1:$F$1)/SUM(B134:F134) -> 3.5454545
A146: =Datos!B16 -> 4. Los integrantes del equipo se consideran mutua e individualmente responsables ante metas colectivas. | B146: =Datos!P16 -> 0 | C146: =Datos!Q16 -> 3 | D146: =Datos!R16 -> 3 | E146: =Datos!S16 -> 5 | F146: =Datos!T16 -> 0 | G146: =SUMPRODUCT(B146:F146,$B$1:$F$1)/SUM(B146:F146) -> 3.1818182
A158: =Datos!B17 -> 5. El rol del líder está claramente definido y los miembros tienen un entendimiento común de éste. | B158: =Datos!P17 -> 0 | C158: =Datos!Q17 -> 0 | D158: =Datos!R17 -> 6 | E158: =Datos!S17 -> 4 | F158: =Datos!T17 -> 1 | G158: =SUMPRODUCT(B158:F158,$B$1:$F$1)/SUM(B158:F158) -> 3.5454545
A170: =Datos!B18 -> 6. Los miembros del equipo cumplen con sus promesas demostrando compromiso respecto de las metas y objetivos individuales. | B170: =Datos!P18 -> 0 | C170: =Datos!Q18 -> 0 | D170: =Datos!R18 -> 2 | E170: =Datos!S18 -> 9 | F170: =Datos!T18 -> 0 | G170: =SUMPRODUCT(B170:F170,$B$1:$F$1)/SUM(B170:F170) -> 3.8181818
A182: =Datos!B19 -> 7. Los miembros del equipo están dispuestos a realizar sacrificios y compartir recursos para optimizar la efectividad del equipo en el logro de las metas. | B182: =Datos!P19 -> 0 | C182: =Datos!Q19 -> 1 | D182: =Datos!R19 -> 5 | E182: =Datos!S19 -> 4 | F182: =Datos!T19 -> 1 | G182: =SUMPRODUCT(B182:F182,$B$1:$F$1)/SUM(B182:F182) -> 3.4545455
A194: =Datos!B20 -> 8. El equipo dedica tiempo a crecer como tal, aumentando el sentido de la solidaridad entre sus miembros. | B194: =Datos!P20 -> 0 | C194: =Datos!Q20 -> 1 | D194: =Datos!R20 -> 2 | E194: =Datos!S20 -> 6 | F194: =Datos!T20 -> 2 | G194: =SUMPRODUCT(B194:F194,$B$1:$F$1)/SUM(B194:F194) -> 3.8181818
A207: =Datos!B21 -> PROCESOS
A208: =Datos!B22 -> 1. Existen acuerdos operativos o reglas de funcionamiento definidas para el equipo. | B208: =Datos!P22 -> 0 | C208: =Datos!Q22 -> 2 | D208: =Datos!R22 -> 2 | E208: =Datos!S22 -> 6 | F208: =Datos!T22 -> 1 | G208: =SUMPRODUCT(B208:F208,$B$1:$F$1)/SUM(B208:F208) -> 3.5454545
A220: =Datos!B23 -> 2. Se revisan periódicamente los procesos en base a su efectividad. | B220: =Datos!P23 -> 2 | C220: =Datos!Q23 -> 1 | D220: =Datos!R23 -> 5 | E220: =Datos!S23 -> 3 | F220: =Datos!T23 -> 0 | G220: =SUMPRODUCT(B220:F220,$B$1:$F$1)/SUM(B220:F220) -> 2.8181818
A232: =Datos!B24 -> 3. La utilización de los recursos del equipo [tiempo y habilidades de sus integrantes] es efectiva. | B232: =Datos!P24 -> 0 | C232: =Datos!Q24 -> 0 | D232: =Datos!R24 -> 3 | E232: =Datos!S24 -> 5 | F232: =Datos!T24 -> 3 | G232: =SUMPRODUCT(B232:F232,$B$1:$F$1)/SUM(B232:F232) -> 4
A244: =Datos!B25 -> 4. Está claro el producto de cada interacción o reunión, tanto del equipo como de los sub-equipos. | B244: =Datos!P25 -> 1 | C244: =Datos!Q25 -> 0 | D244: =Datos!R25 -> 7 | E244: =Datos!S25 -> 3 | F244: =Datos!T25 -> 0 | G244: =SUMPRODUCT(B244:F244,$B$1:$F$1)/SUM(B244:F244) -> 3.0909091
A256: =Datos!B26 -> 5. Se utilizan mecanismos de registro que facilitan el seguimiento de los compromisos. | B256: =Datos!P26 -> 0 | C256: =Datos!Q26 -> 1 | D256: =Datos!R26 -> 6 | E256: =Datos!S26 -> 4 | F256: =Datos!T26 -> 0 | G256: =SUMPRODUCT(B256:F256,$B$1:$F$1)/SUM(B256:F256) -> 3.2727273
A268: =Datos!B27 -> 6. La información circula con la fluidez necesaria para posibilitar la contribución efectiva de los miembros. | B268: =Datos!P27 -> 0 | C268: =Datos!Q27 -> 0 | D268: =Datos!R27 -> 4 | E268: =Datos!S27 -> 5 | F268: =Datos!T27 -> 2 | G268: =SUMPRODUCT(B268:F268,$B$1:$F$1)/SUM(B268:F268) -> 3.8181818
A280: =Datos!B28 -> 7. Existen procesos adecuados para la resolución de conflictos y toma de decisiones. | B280: =Datos!P28 -> 1 | C280: =Datos!Q28 -> 2 | D280: =Datos!R28 -> 4 | E280: =Datos!S28 -> 4 | F280: =Datos!T28 -> 0 | G280: =SUMPRODUCT(B280:F280,$B$1:$F$1)/SUM(B280:F280) -> 3
A292: =Datos!B29 -> 8. Los conflictos se resuelven en forma constructiva. | B292: =Datos!P29 -> 0 | C292: =Datos!Q29 -> 0 | D292: =Datos!R29 -> 3 | E292: =Datos!S29 -> 8 | F292: =Datos!T29 -> 0 | G292: =SUMPRODUCT(B292:F292,$B$1:$F$1)/SUM(B292:F292) -> 3.7272727
A304: =Datos!B30 -> 9. Los procesos son simples, mínimos y flexibles. | B304: =Datos!P30 -> 1 | C304: =Datos!Q30 -> 4 | D304: =Datos!R30 -> 3 | E304: =Datos!S30 -> 2 | F304: =Datos!T30 -> 1 | G304: =SUMPRODUCT(B304:F304,$B$1:$F$1)/SUM(B304:F304) -> 2.8181818
A317: =Datos!B31 -> RELACIONES
A318: =Datos!B32 -> 1. Existe apertura en el equipo para escucharse, desafiarse y vivir con la tensión necesaria para generar cambios. | B318: =Datos!P32 -> 0 | C318: =Datos!Q32 -> 0 | D318: =Datos!R32 -> 4 | E318: =Datos!S32 -> 7 | F318: =Datos!T32 -> 0 | G318: =SUMPRODUCT(B318:F318,$B$1:$F$1)/SUM(B318:F318) -> 3.6363636
A330: =Datos!B33 -> 2. No hay temas indiscutibles en el equipo: todos los temas se traen a la mesa y discuten abiertamente. | B330: =Datos!P33 -> 0 | C330: =Datos!Q33 -> 1 | D330: =Datos!R33 -> 5 | E330: =Datos!S33 -> 4 | F330: =Datos!T33 -> 1 | G330: =SUMPRODUCT(B330:F330,$B$1:$F$1)/SUM(B330:F330) -> 3.4545455
A342: =Datos!B34 -> 3. Los miembros del equipo se dan y reciben retroalimentación sobre comportamientos en tiempo real. | B342: =Datos!P34 -> 1 | C342: =Datos!Q34 -> 2 | D342: =Datos!R34 -> 6 | E342: =Datos!S34 -> 2 | F342: =Datos!T34 -> 0 | G342: =SUMPRODUCT(B342:F342,$B$1:$F$1)/SUM(B342:F342) -> 2.8181818
A354: =Datos!B35 -> 4. Existe respeto incondicional entre los integrantes, y se utilizan las diferencias de opiniones y fortalezas a favor del equipo. | B354: =Datos!P35 -> 0 | C354: =Datos!Q35 -> 1 | D354: =Datos!R35 -> 2 | E354: =Datos!S35 -> 8 | F354: =Datos!T35 -> 0 | G354: =SUMPRODUCT(B354:F354,$B$1:$F$1)/SUM(B354:F354) -> 3.6363636
A366: =Datos!B36 -> 5. El equipo contribuye y alienta a cada integrante a sacar y dar lo mejor de sí. | B366: =Datos!P36 -> 0 | C366: =Datos!Q36 -> 2 | D366: =Datos!R36 -> 4 | E366: =Datos!S36 -> 5 | F366: =Datos!T36 -> 0 | G366: =SUMPRODUCT(B366:F366,$B$1:$F$1)/SUM(B366:F366) -> 3.2727273
A378: =Datos!B37 -> 6. Los miembros del equipo confían en la habilidad del otro, la colaboración, y el apoyo mutuo. | B378: =Datos!P37 -> 0 | C378: =Datos!Q37 -> 1 | D378: =Datos!R37 -> 5 | E378: =Datos!S37 -> 5 | F378: =Datos!T37 -> 0 | G378: =SUMPRODUCT(B378:F378,$B$1:$F$1)/SUM(B378:F378) -> 3.3636364
A390: =Datos!B38 -> 7. Las emociones, los modelos mentales, y los valores individuales se utilizan para el logro de los resultados del equipo. | B390: =Datos!P38 -> 0 | C390: =Datos!Q38 -> 3 | D390: =Datos!R38 -> 5 | E390: =Datos!S38 -> 3 | F390: =Datos!T38 -> 0 | G390: =SUMPRODUCT(B390:F390,$B$1:$F$1)/SUM(B390:F390) -> 3
A402: =Datos!B39 -> 8. Son vistos por los demás como un grupo unido que resulta atractivo a personas que no pertenecen a él. | B402: =Datos!P39 -> 1 | C402: =Datos!Q39 -> 3 | D402: =Datos!R39 -> 6 | E402: =Datos!S39 -> 1 | F402: =Datos!T39 -> 0 | G402: =SUMPRODUCT(B402:F402,$B$1:$F$1)/SUM(B402:F402) -> 2.6363636

Sheet Resultados por cuadrante
A2: CUADRANTE: PROPÓSITO, METAS Y OBJETIVOS | B2: GRADO DE ACUERDO
A3: 1. El equipo tiene un propósito común que es inspirador y entusiasma a sus miembros. El propósito “captura el corazón y el alma” de los miembros del equipo. | B3: ='Resultados por pregunta'!G3 -> 3.2727273
A4: 2. El equipo tiene la capacidad de comunicar dicho propósito al resto de su estructura. | B4: ='Resultados por pregunta'!G12 -> 3
A5: 3. El equipo tiene claro cómo su propósito se conecta y contribuye con el propósito último de la organización. | B5: ='Resultados por pregunta'!G24 -> 3.8181818
A6: 4. El equipo tiene claros sus objetivos o metas de desempeño. | B6: ='Resultados por pregunta'!G36 -> 3.6363636
A7: 5. El proceso de planificación estratégica de la organización se basa en las metas de desempeño de este equipo. | B7: ='Resultados por pregunta'!G48 -> 3.1818182
A8: 6. Existen métricas para los objetivos de desempeño del equipo. | B8: ='Resultados por pregunta'!G60 -> 2.4545455
A9: 7. Los objetivos del equipo quedan registrados en un documento “vivo” al que se recurre y revisa periódicamente. | B9: ='Resultados por pregunta'!G72 -> 2.2727273
A10: 8. El equipo reflexiona acerca de los riesgos para alcanzar las metas individuales, y discute planes para su contingencia. | B10: ='Resultados por pregunta'!G84 -> 2.6363636
A11: 9. Cada miembro del equipo demuestra alineamiento con los valores de la empresa y un elevado nivel de integridad personal. | B11: ='Resultados por pregunta'!G96 -> 3.8181818
A12: PROMEDIO | B12: =AVERAGE(B3:B11) -> 3.1212121
A14: CUADRANTE: ROLES Y RESPONSABILIDADES | B14: GRADO DE ACUERDO
A15: 1. Los roles dentro del equipo están claramente definidos y acordados. | B15: ='Resultados por pregunta'!G110 -> 4.0909091
A16: 2. Las interdependencias entre miembros están claramente definidas y funcionan cabalmente. | B16: ='Resultados por pregunta'!G122 -> 3.7272727
A17: 3. Las metas individuales y su conexión con las metas y objetivos del equipo están definidas claramente. | B17: ='Resultados por pregunta'!G134 -> 3.5454545
A18: 4. Los integrantes del equipo se consideran mutua e individualmente responsables ante metas colectivas. | B18: ='Resultados por pregunta'!G146 -> 3.1818182
A19: 5. El rol del líder está claramente definido y los miembros tienen un entendimiento común de éste. | B19: ='Resultados por pregunta'!G158 -> 3.5454545
A20: 6. Los miembros del equipo cumplen con sus promesas demostrando compromiso respecto de las metas y objetivos individuales. | B20: ='Resultados por pregunta'!G170 -> 3.8181818
A21: 7. Los miembros del equipo están dispuestos a realizar sacrificios y compartir recursos para optimizar la efectividad del equipo en el logro de las metas. | B21: ='Resultados por pregunta'!G182 -> 3.4545455
A22: 8. El equipo dedica tiempo a crecer como tal, aumentando el sentido de la solidaridad entre sus miembros. | B22: ='Resultados por pregunta'!G194 -> 3.8181818
A23: PRIMEDIO | B23: =AVERAGE(B15:B22) -> 3.6477273
A26: CUADRANTE: PROCESOS | B26: GRADO DE ACUERDO
A27: 1. Existen acuerdos operativos o reglas de funcionamiento definidas para el equipo. | B27: ='Resultados por pregunta'!G208 -> 3.5454545
A28: 2. Se revisan periódicamente los procesos en base a su efectividad. | B28: ='Resultados por pregunta'!G220 -> 2.8181818
A29: 3. La utilización de los recursos del equipo [tiempo y habilidades de sus integrantes] es efectiva. | B29: ='Resultados por pregunta'!G232 -> 4
A30: 4. Está claro el producto de cada interacción o reunión, tanto del equipo como de los sub-equipos. | B30: ='Resultados por pregunta'!G244 -> 3.0909091
A31: 5. Se utilizan mecanismos de registro que facilitan el seguimiento de los compromisos. | B31: ='Resultados por pregunta'!G256 -> 3.2727273
A32: 6. La información circula con la fluidez necesaria para posibilitar la contribución efectiva de los miembros. | B32: ='Resultados por pregunta'!G268 -> 3.8181818
A33: 7. Existen procesos adecuados para la resolución de conflictos y toma de decisiones. | B33: ='Resultados por pregunta'!G280 -> 3
A34: 8. Los conflictos se resuelven en forma constructiva. | B34: ='Resultados por pregunta'!G292 -> 3.7272727
A35: 9. Los procesos son simples, mínimos y flexibles. | B35: ='Resultados por pregunta'!G304 -> 2.8181818
A36: PROMEDIO | B36: =AVERAGE(B27:B35) -> 3.3434343
A38: CUADRANTE: RELACIONES | B38: GRADO DE ACUERDO
A39: 1. Existe apertura en el equipo para escucharse, desafiarse y vivir con la tensión necesaria para generar cambios. | B39: ='Resultados por pregunta'!G318 -> 3.6363636
A40: 2. No hay temas indiscutibles en el equipo: todos los temas se traen a la mesa y discuten abiertamente. | B40: ='Resultados por pregunta'!G330 -> 3.4545455
A41: 3. Los miembros del equipo se dan y reciben retroalimentación sobre comportamientos en tiempo real. | B41: ='Resultados por pregunta'!G342 -> 2.8181818
A42: 4. Existe respeto incondicional entre los integrantes, y se utilizan las diferencias de opiniones y fortalezas a favor del equipo. | B42: ='Resultados por pregunta'!G354 -> 3.6363636
A43: 5. El equipo contribuye y alienta a cada integrante a sacar y dar lo mejor de sí. | B43: ='Resultados por pregunta'!G366 -> 3.2727273
A44: 6. Los miembros del equipo confían en la habilidad del otro, la colaboración, y el apoyo mutuo. | B44: ='Resultados por pregunta'!G378 -> 3.3636364
A45: 7. Las emociones, los modelos mentales, y los valores individuales se utilizan para el logro de los resultados del equipo. | B45: ='Resultados por pregunta'!G390 -> 3
...
